Workbook
Name 고객사: "TextBox 5"
Name 보안점검결과요약_대상: OFFSET([1]hidden!$N$26,0,0,COUNTA([1]hidden!$B$26:$B$45))
Name 보안점검결과요약_취약개수: OFFSET([1]hidden!$O$26,0,0,COUNTA([1]hidden!$C$26:$C$45))
Name 보안점검결과총평_대상: OFFSET([1]hidden!$B$26,0,0,COUNTA([1]hidden!$B$26:$B$30))
Name 보안점검결과총평_점수: OFFSET([1]hidden!$D$26,0,0,COUNTA([1]hidden!$D$26:$D$30))
Name 보안점검결과총평_평균: OFFSET([1]hidden!$E$26,0,0,COUNTA([1]hidden!$E$26:$E$30))
Name 이행점검결과요약_대상: OFFSET([1]hidden!$Q$26,0,0,COUNTA([1]hidden!$G$26:$G$45))
Name 이행점검결과요약_취약개수: OFFSET([1]hidden!$R$26,0,0,COUNTA([1]hidden!$H$26:$H$45))
Name 이행점검결과총평_대상: OFFSET([1]hidden!$G$26,0,0,COUNTA([1]hidden!$G$26:$G$30))
Name 이행점검결과총평_보안점수: OFFSET([1]hidden!$K$26,0,0,COUNTA([1]hidden!$G$26:$G$30))
Name 이행점검결과총평_이행점수: OFFSET([1]hidden!$I$26,0,0,COUNTA([1]hidden!$I$26:$I$30))
Name 이행점검결과총평_평균: OFFSET([1]hidden!$J$26,0,0,COUNTA([1]hidden!$J$26:$J$30))

Sheet hidden
A1: [차트 보조 데이터] 보안점검 결과 평가점수 하위 5개 서버 자동 추출 테이블 ※ 보안점검 결과 시트의 평가점수(76행)를 기준으로 하위 5개 서버를 자동 정렬합니다. 서버 추가·변경 시 자동 갱신됩니다.
A2: 점검 대상 서버 수 (자동) | B2: =COUNTA('Ⅳ. 보안점검 결과'!$G$4:$XFD$4) -> 0
A3: 서버명 | B3: 평가점수
A4: =IFERROR(INDEX('Ⅳ. 보안점검 결과'!$G$4:$XFD$4,MATCH(SMALL('Ⅳ. 보안점검 결과'!$G$76:$XFD$76,1),'Ⅳ. 보안점검 결과'!$G$76:$XFD$76,0)),"") | B4: =IFERROR(SMALL('Ⅳ. 보안점검 결과'!$G$76:$XFD$76,1),"")
A5: {=IFERROR(INDEX('Ⅳ. 보안점검 결과'!$G$4:$XFD$4,MATCH(1,('Ⅳ. 보안점검 결과'!$G$76:$XFD$76=SMALL('Ⅳ. 보안점검 결과'!$G$76:$XFD$76,2))*(COUNTIF(A$4:A4,'Ⅳ. 보안점검 결과'!$G$4:$XFD$4)=0),0)),"")} | B5: =IFERROR(SMALL('Ⅳ. 보안점검 결과'!$G$76:$XFD$76,2),"")
A6: {=IFERROR(INDEX('Ⅳ. 보안점검 결과'!$G$4:$XFD$4,MATCH(1,('Ⅳ. 보안점검 결과'!$G$76:$XFD$76=SMALL('Ⅳ. 보안점검 결과'!$G$76:$XFD$76,3))*(COUNTIF(A$4:A5,'Ⅳ. 보안점검 결과'!$G$4:$XFD$4)=0),0)),"")} | B6: =IFERROR(SMALL('Ⅳ. 보안점검 결과'!$G$76:$XFD$76,3),"")
A7: {=IFERROR(INDEX('Ⅳ. 보안점검 결과'!$G$4:$XFD$4,MATCH(1,('Ⅳ. 보안점검 결과'!$G$76:$XFD$76=SMALL('Ⅳ. 보안점검 결과'!$G$76:$XFD$76,4))*(COUNTIF(A$4:A6,'Ⅳ. 보안점검 결과'!$G$4:$XFD$4)=0),0)),"")} | B7: =IFERROR(SMALL('Ⅳ. 보안점검 결과'!$G$76:$XFD$76,4),"")
A8: {=IFERROR(INDEX('Ⅳ. 보안점검 결과'!$G$4:$XFD$4,MATCH(1,('Ⅳ. 보안점검 결과'!$G$76:$XFD$76=SMALL('Ⅳ. 보안점검 결과'!$G$76:$XFD$76,5))*(COUNTIF(A$4:A7,'Ⅳ. 보안점검 결과'!$G$4:$XFD$4)=0),0)),"")} | B8: =IFERROR(SMALL('Ⅳ. 보안점검 결과'!$G$76:$XFD$76,5),"")
A10: [차트 보조 데이터] 이행점검 결과 평가점수 하위 5개 서버 자동 추출 테이블 ※ 이행점검 결과 시트의 평가점수(76행)를 기준으로 하위 5개 서버를 자동 정렬합니다. 서버 추가·변경 시 자동 갱신됩니다.
A11: 점검 대상 서버 수 (자동) | B11: =COUNTA('Ⅳ. 보안점검 결과'!$G$4:$XFD$4) -> 0
A12: 서버명 | B12: 평가점수
A13: =IFERROR(INDEX('Ⅴ. 이행점검 결과'!$G$4:$XFD$4,MATCH(SMALL('Ⅴ. 이행점검 결과'!$G$76:$XFD$76,1),'Ⅴ. 이행점검 결과'!$G$76:$XFD$76,0)),"") | B13: =IFERROR(SMALL('Ⅴ. 이행점검 결과'!$G$76:$XFD$76,1),"")
A14: {=IFERROR(INDEX('Ⅴ. 이행점검 결과'!$G$4:$XFD$4,MATCH(1,('Ⅴ. 이행점검 결과'!$G$76:$XFD$76=SMALL('Ⅴ. 이행점검 결과'!$G$76:$XFD$76,2))*(COUNTIF(A$13:A13,'Ⅴ. 이행점검 결과'!$G$4:$XFD$4)=0),0)),"")} | B14: =IFERROR(SMALL('Ⅴ. 이행점검 결과'!$G$76:$XFD$76,2),"")
A15: {=IFERROR(INDEX('Ⅴ. 이행점검 결과'!$G$4:$XFD$4,MATCH(1,('Ⅴ. 이행점검 결과'!$G$76:$XFD$76=SMALL('Ⅴ. 이행점검 결과'!$G$76:$XFD$76,3))*(COUNTIF(A$13:A14,'Ⅴ. 이행점검 결과'!$G$4:$XFD$4)=0),0)),"")} | B15: =IFERROR(SMALL('Ⅴ. 이행점검 결과'!$G$76:$XFD$76,3),"")
A16: {=IFERROR(INDEX('Ⅴ. 이행점검 결과'!$G$4:$XFD$4,MATCH(1,('Ⅴ. 이행점검 결과'!$G$76:$XFD$76=SMALL('Ⅴ. 이행점검 결과'!$G$76:$XFD$76,4))*(COUNTIF(A$13:A15,'Ⅴ. 이행점검 결과'!$G$4:$XFD$4)=0),0)),"")} | B16: =IFERROR(SMALL('Ⅴ. 이행점검 결과'!$G$76:$XFD$76,4),"")
A17: {=IFERROR(INDEX('Ⅴ. 이행점검 결과'!$G$4:$XFD$4,MATCH(1,('Ⅴ. 이행점검 결과'!$G$76:$XFD$76=SMALL('Ⅴ. 이행점검 결과'!$G$76:$XFD$76,5))*(COUNTIF(A$13:A16,'Ⅴ. 이행점검 결과'!$G$4:$XFD$4)=0),0)),"")} | B17: =IFERROR(SMALL('Ⅴ. 이행점검 결과'!$G$76:$XFD$76,5),"")

Sheet Ⅰ. 표지
A7: 업체명
A11: 주요정보통신기반시설 서버(LINUX/UNIX) 이행점검 상세 결과보고서

Sheet Ⅱ. 개요
A2: Ⅰ. 개 요
B4: 1.1. 점검 목적
B5: ='Ⅰ. 표지'!A7 &"에서 운영 중인 서버를 대상으로 보안점검을 수행하여 현재의 보안 수준을 파악, 발견된 취약점에 대한 기술적인 대책을 수립함으로써 의 IT환경을 더욱 신뢰성 있고 안전한 환경을 구축하여, 서비스의 안정성을 확보하는데 있습니다." -> 업체명에서 운영 중인 서버를 대상으로 보안점검을 수행하여 현재의 보안 수준을 파악, 발견된 취약점에 대한 기술적인 대책을 수립함으로써 의 IT환경을 더욱 신뢰성 있고 안전한 환경을 구축하여, 서비스의 안정성을 확보하는데 있습니다.
B8: 1.2. 기대 효과
B9: → 보안점검을 통해 운영 중인 시스템상에 존재하는 취약점 조기에 발견 → 도출된 결과에 대하여 취약점의 심각성 등을 심층적 분석 → 현재의 보안수준을 평가하고 이에 대한 종합적인 대응책 도출 → 도출된 대응책을 통해 운영 중인 웹 서비스의 보안성 강화
B14: 1.3. 점검 방법
B15: 서버 취약점 점검은 시스템의 중요 파일의 변조 가능성 및 계정 정보의 정책 등을 점검하여 시스템이 보다 안전한 환경에서 운영될 수 있도록 하는데 목적을 둡니다.
D17: 구 분 | J17: 점검 방법 | S17: 비 고
D18: 주요정보통신기반시설 서버(LINUX/UNIX) 이행점검 | J18: 체크리스트를 이용하여 보안지수를 점검 | S18: 인터뷰
S19: 수동점검
S20: 스크립트
B22: 1.4. 점검 항목
B23: ◎ 점검 등급
D24: 구 분 | J24: 설 명
D25: 양호 | J25: 점검 항목의 보안 설정이 잘 적용되어 있음
D26: 취약 | J26: 점검 항목의 보안 설정이 적용되어 있지 않음
D27: N/A | J27: 점검 항목이 해당 시스템과 관련이 없음
D28: 수동점검 | J28: 점검 항목이 취약한 설정으로 되어 있지만 담당자가 인지하고 있음
B30: ◎ 위험도
D31: 구 분 | J31: 설 명
D32: 상 | J32: 관리자 권한을 획득하거나 시스템 정지 가능
D33: 중 | J33: 일반권한을 획득하거나 주요 정보 유출 가능
D34: 하 | J34: 시스템 정보 등의 위협은 가능하나 영향력 미비

Sheet Ⅲ. 점검대상
A2: Ⅲ. 점검 대상
B4: 순서 | C4: 서버명 | D4: HostName | E4: IP Address | F4: OS/Version | G4: 부서/담당자 | H4: 비고

Sheet Ⅳ. 보안점검 결과
A2: Ⅳ. 보안점검 결과
B4: 구분 | C4: 순번 | D4: 점검항목 | E4: 중요도 | F4: 항목별 취약수
B5: 1. 계정관리 | C5: U-01 | D5: root 계정 원격 접속 제한 | E5: 상 | F5: =COUNTIF(G5:XFD5,"취약") -> 0
C6: U-02 | D6: 비밀번호 관리정책 설정 | E6: 상 | F6: =COUNTIF(G6:XFD6,"취약") -> 0
C7: U-03 | D7: 계정 잠금 임계값 설정 | E7: 상 | F7: =COUNTIF(G7:XFD7,"취약") -> 0
C8: U-04 | D8: 비밀번호 파일 보호 | E8: 상 | F8: =COUNTIF(G8:XFD8,"취약") -> 0
C9: U-05 | D9: root 이외의 UID가 '0' 금지 | E9: 중 | F9: =COUNTIF(G9:XFD9,"취약") -> 0
C10: U-06 | D10: 사용자 계정 su 기능 제한 | E10: 상 | F10: =COUNTIF(G10:XFD10,"취약") -> 0
C11: U-07 | D11: 불필요한 계정 제거 | E11: 하 | F11: =COUNTIF(G11:XFD11,"취약") -> 0
C12: U-08 | D12: 관리자 그룹에 최소한의 계정 포함 | E12: 중 | F12: =COUNTIF(G12:XFD12,"취약") -> 0
C13: U-09 | D13: 계정이 존재하지 않는 GID 금지 | E13: 하 | F13: =COUNTIF(G13:XFD13,"취약") -> 0
C14: U-10 | D14: 동일한 UID 금지 | E14: 중 | F14: =COUNTIF(G14:XFD14,"취약") -> 0
C15: U-11 | D15: 사용자 shell 점검 | E15: 하 | F15: =COUNTIF(G15:XFD15,"취약") -> 0
C16: U-12 | D16: 세션 종료 시간 설정 | E16: 하 | F16: =COUNTIF(G16:XFD16,"취약") -> 0
C17: U-13 | D17: 안전한 비밀번호 암호화 알고리즘 사용 | E17: 중 | F17: =COUNTIF(G17:XFD17,"취약") -> 0
B18: 2. 파일 및 디렉터리 관리 | C18: U-14 | D18: root 홈, 패스 디렉터리 권한 및 패스 설정 | E18: 상 | F18: =COUNTIF(G18:XFD18,"취약") -> 0
C19: U-15 | D19: 파일 및 디렉터리 소유자 설정 | E19: 상 | F19: =COUNTIF(G19:XFD19,"취약") -> 0
C20: U-16 | D20: /etc/passwd 파일 소유자 및 권한 설정 | E20: 상 | F20: =COUNTIF(G20:XFD20,"취약") -> 0
C21: U-17 | D21: 시스템 시작 스크립트 권한 설정 | E21: 상 | F21: =COUNTIF(G21:XFD21,"취약") -> 0
C22: U-18 | D22: /etc/shadow 파일의 소유자가 root이고, 권한이 400 이하인 경우 | E22: 상 | F22: =COUNTIF(G22:XFD22,"취약") -> 0
C23: U-19 | D23: /etc/hosts 파일 소유자 및 권한 설정 | E23: 상 | F23: =COUNTIF(G23:XFD23,"취약") -> 0
C24: U-20 | D24: /etc/(x)inetd.conf 파일 소유자 및 권한 설정 | E24: 상 | F24: =COUNTIF(G24:XFD24,"취약") -> 0
C25: U-21 | D25: /etc/(r)syslog.conf 파일 소유자 및 권한 설정 | E25: 상 | F25: =COUNTIF(G25:XFD25,"취약") -> 0
C26: U-22 | D26: /etc/services 파일 소유자 및 권한 설정 | E26: 상 | F26: =COUNTIF(G26:XFD26,"취약") -> 0
C27: U-23 | D27: SUID, SGID, Sticky bit 설정 파일 점검 | E27: 상 | F27: =COUNTIF(G27:XFD27,"취약") -> 0
C28: U-24 | D28: 사용자, 시스템 환경변수 파일 소유자 및 권한 설정 | E28: 상 | F28: =COUNTIF(G28:XFD28,"취약") -> 0
C29: U-25 | D29: world writable 파일 점검 | E29: 상 | F29: =COUNTIF(G29:XFD29,"취약") -> 0
C30: U-26 | D30: /dev에 존재하지 않는 device 파일 점검 | E30: 상 | F30: =COUNTIF(G30:XFD30,"취약") -> 0
... C37: U-33 | D37: 숨겨진 파일 및 디렉토리 검색 및 제거 | E37: 하 | F37: =COUNTIF(G37:XFD37,"취약") -> 0
B38: 3. 서비스 관리 | C38: U-34 | D38: Finger 서비스 비활성화 | E38: 상 | F38: =COUNTIF(G38:XFD38,"취약") -> 0
C39: U-35 | D39: 공유 서비스에 대한 익명 접근 제한 설정 | E39: 상 | F39: =COUNTIF(G39:XFD39,"취약") -> 0
C40: U-36 | D40: r 계열 서비스 비활성화 | E40: 상 | F40: =COUNTIF(G40:XFD40,"취약") -> 0
C41: U-37 | D41: crontab 설정파일 권한 설정 미흡 | E41: 상 | F41: =COUNTIF(G41:XFD41,"취약") -> 0
C42: U-38 | D42: DoS 공격에 취약한 서비스 비활성화 | E42: 상 | F42: =COUNTIF(G42:XFD42,"취약") -> 0
C43: U-39 | D43: 불필요한 NFS 서비스 비활성화 | E43: 상 | F43: =COUNTIF(G43:XFD43,"취약") -> 0
C44: U-40 | D44: NFS 접근 통제 | E44: 상 | F44: =COUNTIF(G44:XFD44,"취약") -> 0
C45: U-41 | D45: 불필요한 automountd 제거 | E45: 상 | F45: =COUNTIF(G45:XFD45,"취약") -> 0
C46: U-42 | D46: 불필요한 RPC 서비스 비활성화 | E46: 상 | F46: =COUNTIF(G46:XFD46,"취약") -> 0
C47: U-43 | D47: NIS, NIS+ 점검 | E47: 상 | F47: =COUNTIF(G47:XFD47,"취약") -> 0
C48: U-44 | D48: tftp, talk 서비스 비활성화 | E48: 상 | F48: =COUNTIF(G48:XFD48,"취약") -> 0
...

Sheet 대응방안
A1: 대응방안
B3: 구분 | C3: 순번 | D3: 점검항목 | F3: 중요도 | G3: 간략 권고 사항 | H3: 비고
B4: 1. 계정관리 | C4: U-01 | D4: root 계정 원격 접속 제한 | F4: 상 | G4: 원격 접속 시 root 계정으로 접속할 수 없도록 파일 내용 설정
C5: U-02 | D5: 비밀번호 관리정책 설정 | F5: 상 | G5: root 계정을 포함한 사용자 계정의 비밀번호를 영문, 숫자, 특수문자를 포함하여 최소 8자리 이상 및 최소 사용 기간 1일, 최대 사용 기간 90일, 최근 비밀번호 기억 4회 이상으로 설정
C6: U-03 | D6: 계정 잠금 임계값 설정 | F6: 상 | G6: 계정 잠금 임계값을 10회 이하로 설정
C7: U-04 | D7: 비밀번호 파일 보호 | F7: 상 | G7: 비밀번호 암호화 저장·관리 설정
C8: U-05 | D8: root 이외의 UID가 '0' 금지 | F8: 중 | G8: UID가 0으로 설정된 계정을 0 이외의 중복되지 않은 UID로 변경 또는 불필요한 계정인 경우 제거하도록 설정
C9: U-06 | D9: 사용자 계정 su 기능 제한 | F9: 상 | G9: PAM 모듈 설정 또는 su 명령어 허용 그룹 생성 후 su 명령어 일반 사용자 권한 제거하도록 설정
C10: U-07 | D10: 불필요한 계정 제거 | F10: 하 | G10: 시스템의 존재하는 계정 확인 후 불필요한 계정 제거하도록 설정
C11: U-08 | D11: 관리자 그룹에 최소한의 계정 포함 | F11: 중 | G11: 관리자 그룹에 등록된 계정 확인 후 불필요한 계정 제거하도록 설정
C12: U-09 | D12: 계정이 존재하지 않는 GID 금지 | F12: 하 | G12: 불필요한 그룹이 존재하는 경우 관리자와 검토하여 제거하도록 설정
C13: U-10 | D13: 동일한 UID 금지 | F13: 중 | G13: 동일한 UID를 가진 사용자 계정의 UID를 중복되지 않도록 변경하도록 설정
C14: U-11 | D14: 사용자 shell 점검 | F14: 하 | G14: 로그인이 필요하지 않은 계정에 대해 /bin/false(/sbin/nologin) 쉘 부여 설정
C15: U-12 | D15: 세션 종료 시간 설정 | F15: 하 | G15: 600초(10분) 동안 입력이 없는 경우 접속된 Session을 끊도록 설정
C16: U-13 | D16: 안전한 비밀번호 암호화 알고리즘 사용 | F16: 중 | G16: SHA-2 이상의 안전한 비밀번호 암호화 알고리즘 적용 설정
B17: 2. 파일 및 디렉터리 관리 | C17: U-14 | D17: root 홈, 패스 디렉터리 권한 및 패스 설정 | F17: 상 | G17: root 계정의 환경설정 파일(/.profile, /.bashrc 등)과 시스템 환경설정파일(/etc/profile 등)에 설정된 PATH 환경변수에서 현재 디렉터리를 나타내는 "." 을 PATH 환경변수의 마지막으로 이동하도록 설정
C18: U-15 | D18: 파일 및 디렉터리 소유자 설정 | F18: 상 | G18: 소유자가 존재하지 않는 파일 및 디렉터리 제거 또는 소유자 변경 설정
C19: U-16 | D19: /etc/passwd 파일 소유자 및 권한 설정 | F19: 상 | G19: /etc/passwd 파일 소유자 및 권한 변경 설정
C20: U-17 | D20: 시스템 시작 스크립트 권한 설정 | F20: 상 | G20: 시스템 시작 스크립트 파일 소유자 및 권한 변경 설정
C21: U-18 | D21: /etc/shadow 파일의 소유자가 root이고, 권한이 400 이하인 경우 | F21: 상 | G21: /etc/shadow 파일 소유자 및 권한 변경 설정
C22: U-19 | D22: /etc/hosts 파일 소유자 및 권한 설정 | F22: 상 | G22: /etc/hosts 파일 소유자 및 권한 변경 설정
C23: U-20 | D23: /etc/(x)inetd.conf 파일 소유자 및 권한 설정 | F23: 상 | G23: /etc/(x)inetd.conf 파일 소유자 및 권한 변경 설정
C24: U-21 | D24: /etc/(r)syslog.conf 파일 소유자 및 권한 설정 | F24: 상 | G24: /etc/(r)syslog.conf 파일 소유자 및 권한 변경 설정
C25: U-22 | D25: /etc/services 파일 소유자 및 권한 설정 | F25: 상 | G25: /etc/services 파일 소유자 및 권한 변경 설정
C26: U-23 | D26: SUID, SGID, Sticky bit 설정 파일 점검 | F26: 상 | G26: 불피요한 SUID, SGID 권한 또는 해당 파일 제거하도록 설정 애플리케이션에서 생성한 파일이나 사용자가 임의로 생성한 파일 등 의심스럽거나 특이한 파일에 SUID 권한이 부여된 경우 제거하도록 설정
C27: U-24 | D27: 사용자, 시스템 환경변수 파일 소유자 및 권한 설정 | F27: 상 | G27: 환경변수 파일의 일반 사용자 쓰기 권한 제거하도록 설정
C28: U-25 | D28: world writable 파일 점검 | F28: 상 | G28: world writable 파일 존재 여부를 확인하고 불필요한 경우 제거하도록 설정
C29: U-26 | D29: /dev에 존재하지 않는 device 파일 점검 | F29: 상 | G29: major, minor number를 가지지 않는 device 파일 제거하도록 설정
... C36: U-33 | D36: 숨겨진 파일 및 디렉토리 검색 및 제거 | F36: 하 | G36: ls -al 명령어로 숨겨진 파일 존재 파악 후 불법적이거나 의심스러운 파일을 제거하도록 설정
B37: 3. 서비스 관리 | C37: U-34 | D37: Finger 서비스 비활성화 | F37: 상 | G37: Finger 서비스 비활성화 설정
C38: U-35 | D38: 공유 서비스에 대한 익명 접근 제한 설정 | F38: 상 | G38: 공유 서비스의 익명 접근 제한 설정
C39: U-36 | D39: r 계열 서비스 비활성화 | F39: 상 | G39: 불필요한 r 계열 서비스 중지 및 비활성화 설정
C40: U-37 | D40: crontab 설정파일 권한 설정 미흡 | F40: 상 | G40: crontab 및 at 명령어 파일 권한 750 이하, cron 및 at 관련 소유자 및 파일 권한 640 이하 설정
C41: U-38 | D41: DoS 공격에 취약한 서비스 비활성화 | F41: 상 | G41: echo, discard, daytime, chargen, ntp, dns, snmp 등의 서비스 비활성화 설정
C42: U-39 | D42: 불필요한 NFS 서비스 비활성화 | F42: 상 | G42: NFS 서비스를 사용하지 않는 경우 서비스 중지 및 비활성화 설정
C43: U-40 | D43: NFS 접근 통제 | F43: 상 | G43: NFS 서비스를 사용하지 않는 경우 서비스 중지 및 비활성화 설정 불가피하게 사용 시 접근 통제 설정 및 NFS 설정 파일 접근 권한 644 설정
C44: U-41 | D44: 불필요한 automountd 제거 | F44: 상 | G44: automountd 서비스 비활성화 설정
C45: U-42 | D45: 불필요한 RPC 서비스 비활성화 | F45: 상 | G45: 불필요한 RPC 서비스 중지 및 비활성화 설정
C46: U-43 | D46: NIS, NIS+ 점검 | F46: 상 | G46: NIS 관련 서비스 비활성화 설정
C47: U-44 | D47: tftp, talk 서비스 비활성화 | F47: 상 | G47: 불필요한 tftp, talk, ntalk 서비스 비활성화 설정
...

Sheet Ⅳ. 보안점검 총평
A2: Ⅳ. 보안점검 총평
B4: 4.1. 총 평
C6: ='Ⅰ. 표지'!A7 & " 서버(LINUX/UNIX)의 보안점검 결과 전체 점검항목중에서 " & 'Ⅳ. 보안점검 결과'!F72 & "개(상 " & 'Ⅳ. 보안점검 결과'!F73 &"개, 중 " & 'Ⅳ. 보안점검 결과'!F74 &"개, 하 " & 'Ⅳ. 보안점검 결과'!F75 &"개)의 취약점이 발견되었습니다." -> 업체명 서버(LINUX/UNIX)의 보안점검 결과 전체 점검항목중에서 0개(상 0개, 중 0개, 하 0개)의 취약점이 발견되었습니다.
C9: ="취약점 분석 평가 점수가 가장 낮은 대상은 '" & IFERROR(INDEX('Ⅳ. 보안점검 결과'!G4:XFD4, MATCH(MIN('Ⅳ. 보안점검 결과'!G76:XFD76), 'Ⅳ. 보안점검 결과'!G76:XFD76, 0)), "서버이름") & "' 입니다. 전체 대상의 취약점 분석 평가 평균 점수는 " & IFERROR(ROUND(AVERAGE('Ⅳ. 보안점검 결과'!G76:XFD76)*100, 1), "00") & "점 입니다." -> 취약점 분석 평가 점수가 가장 낮은 대상은 '서버이름' 입니다. 전체 대상의 취약점 분석 평가 평균 점수는 00점 입니다.
C13: ◎ 취약점 분석 평가 점수 (취약점 수 상위 5항목) | Q13: ◎ 위험도별 발견 취약점 수

Sheet Ⅴ. 이행점검 결과
A2: Ⅴ. 이행점검 결과
B4: 구분 | C4: 순번 | D4: 점검항목 | E4: 중요도 | F4: 항목별 취약수
B5: 1. 계정관리 | C5: U-01 | D5: root 계정 원격 접속 제한 | E5: 상 | F5: =COUNTIF(G5:XFD5,"취약") -> 0
C6: U-02 | D6: 비밀번호 관리정책 설정 | E6: 상 | F6: =COUNTIF(G6:XFD6,"취약") -> 0
C7: U-03 | D7: 계정 잠금 임계값 설정 | E7: 상 | F7: =COUNTIF(G7:XFD7,"취약") -> 0
C8: U-04 | D8: 비밀번호 파일 보호 | E8: 상 | F8: =COUNTIF(G8:XFD8,"취약") -> 0
C9: U-05 | D9: root 이외의 UID가 '0' 금지 | E9: 중 | F9: =COUNTIF(G9:XFD9,"취약") -> 0
C10: U-06 | D10: 사용자 계정 su 기능 제한 | E10: 상 | F10: =COUNTIF(G10:XFD10,"취약") -> 0
C11: U-07 | D11: 불필요한 계정 제거 | E11: 하 | F11: =COUNTIF(G11:XFD11,"취약") -> 0
C12: U-08 | D12: 관리자 그룹에 최소한의 계정 포함 | E12: 중 | F12: =COUNTIF(G12:XFD12,"취약") -> 0
C13: U-09 | D13: 계정이 존재하지 않는 GID 금지 | E13: 하 | F13: =COUNTIF(G13:XFD13,"취약") -> 0
C14: U-10 | D14: 동일한 UID 금지 | E14: 중 | F14: =COUNTIF(G14:XFD14,"취약") -> 0
C15: U-11 | D15: 사용자 shell 점검 | E15: 하 | F15: =COUNTIF(G15:XFD15,"취약") -> 0
C16: U-12 | D16: 세션 종료 시간 설정 | E16: 하 | F16: =COUNTIF(G16:XFD16,"취약") -> 0
C17: U-13 | D17: 안전한 비밀번호 암호화 알고리즘 사용 | E17: 중 | F17: =COUNTIF(G17:XFD17,"취약") -> 0
B18: 2. 파일 및 디렉터리 관리 | C18: U-14 | D18: root 홈, 패스 디렉터리 권한 및 패스 설정 | E18: 상 | F18: =COUNTIF(G18:XFD18,"취약") -> 0
C19: U-15 | D19: 파일 및 디렉터리 소유자 설정 | E19: 상 | F19: =COUNTIF(G19:XFD19,"취약") -> 0
C20: U-16 | D20: /etc/passwd 파일 소유자 및 권한 설정 | E20: 상 | F20: =COUNTIF(G20:XFD20,"취약") -> 0
C21: U-17 | D21: 시스템 시작 스크립트 권한 설정 | E21: 상 | F21: =COUNTIF(G21:XFD21,"취약") -> 0
C22: U-18 | D22: /etc/shadow 파일의 소유자가 root이고, 권한이 400 이하인 경우 | E22: 상 | F22: =COUNTIF(G22:XFD22,"취약") -> 0
C23: U-19 | D23: /etc/hosts 파일 소유자 및 권한 설정 | E23: 상 | F23: =COUNTIF(G23:XFD23,"취약") -> 0
C24: U-20 | D24: /etc/(x)inetd.conf 파일 소유자 및 권한 설정 | E24: 상 | F24: =COUNTIF(G24:XFD24,"취약") -> 0
C25: U-21 | D25: /etc/(r)syslog.conf 파일 소유자 및 권한 설정 | E25: 상 | F25: =COUNTIF(G25:XFD25,"취약") -> 0
C26: U-22 | D26: /etc/services 파일 소유자 및 권한 설정 | E26: 상 | F26: =COUNTIF(G26:XFD26,"취약") -> 0
C27: U-23 | D27: SUID, SGID, Sticky bit 설정 파일 점검 | E27: 상 | F27: =COUNTIF(G27:XFD27,"취약") -> 0
C28: U-24 | D28: 사용자, 시스템 환경변수 파일 소유자 및 권한 설정 | E28: 상 | F28: =COUNTIF(G28:XFD28,"취약") -> 0
C29: U-25 | D29: world writable 파일 점검 | E29: 상 | F29: =COUNTIF(G29:XFD29,"취약") -> 0
C30: U-26 | D30: /dev에 존재하지 않는 device 파일 점검 | E30: 상 | F30: =COUNTIF(G30:XFD30,"취약") -> 0
... C37: U-33 | D37: 숨겨진 파일 및 디렉토리 검색 및 제거 | E37: 하 | F37: =COUNTIF(G37:XFD37,"취약") -> 0
B38: 3. 서비스 관리 | C38: U-34 | D38: Finger 서비스 비활성화 | E38: 상 | F38: =COUNTIF(G38:XFD38,"취약") -> 0
C39: U-35 | D39: 공유 서비스에 대한 익명 접근 제한 설정 | E39: 상 | F39: =COUNTIF(G39:XFD39,"취약") -> 0
C40: U-36 | D40: r 계열 서비스 비활성화 | E40: 상 | F40: =COUNTIF(G40:XFD40,"취약") -> 0
C41: U-37 | D41: crontab 설정파일 권한 설정 미흡 | E41: 상 | F41: =COUNTIF(G41:XFD41,"취약") -> 0
C42: U-38 | D42: DoS 공격에 취약한 서비스 비활성화 | E42: 상 | F42: =COUNTIF(G42:XFD42,"취약") -> 0
C43: U-39 | D43: 불필요한 NFS 서비스 비활성화 | E43: 상 | F43: =COUNTIF(G43:XFD43,"취약") -> 0
C44: U-40 | D44: NFS 접근 통제 | E44: 상 | F44: =COUNTIF(G44:XFD44,"취약") -> 0
C45: U-41 | D45: 불필요한 automountd 제거 | E45: 상 | F45: =COUNTIF(G45:XFD45,"취약") -> 0
C46: U-42 | D46: 불필요한 RPC 서비스 비활성화 | E46: 상 | F46: =COUNTIF(G46:XFD46,"취약") -> 0
C47: U-43 | D47: NIS, NIS+ 점검 | E47: 상 | F47: =COUNTIF(G47:XFD47,"취약") -> 0
C48: U-44 | D48: tftp, talk 서비스 비활성화 | E48: 상 | F48: =COUNTIF(G48:XFD48,"취약") -> 0
...

Sheet Ⅴ. 이행점검 총평
A2: Ⅴ. 이행점검 총평
B4: 5.1. 총 평
C6: ='Ⅰ. 표지'!A7 & " 서버(LINUX/UNIX)의 이행점검 결과 전체 점검항목중에서 " & 'Ⅴ. 이행점검 결과'!F72 & "개(상 " & 'Ⅴ. 이행점검 결과'!F73 &"개, 중 " & 'Ⅴ. 이행점검 결과'!F74 &"개, 하 " & 'Ⅴ. 이행점검 결과'!F75 &"개)의 취약점이 발견되었습니다." -> 업체명 서버(LINUX/UNIX)의 이행점검 결과 전체 점검항목중에서 0개(상 0개, 중 0개, 하 0개)의 취약점이 발견되었습니다.
C9: ="취약점 분석 평가 점수가 가장 낮은 대상은 '" & IFERROR(INDEX('Ⅴ. 이행점검 결과'!G4:XFD4, MATCH(MIN('Ⅴ. 이행점검 결과'!G76:XFD76), 'Ⅴ. 이행점검 결과'!G76:XFD76, 0)), "서버이름") & "' 입니다. 전체 대상의 취약점 분석 평가 평균 점수는 " & IFERROR(ROUND(AVERAGE('Ⅴ. 이행점검 결과'!G76:XFD76)*100, 1), "00") & "점 입니다." -> 취약점 분석 평가 점수가 가장 낮은 대상은 '서버이름' 입니다. 전체 대상의 취약점 분석 평가 평균 점수는 00점 입니다.
C13: ◎ 취약점 분석 평가 점수 (취약점 수 상위 5항목) | Q13: ◎ 위험도별 발견 취약점 수

Sheet template
A1: Ⅵ. 취약점 상세 현황
B4: 서버이름 | E4: OS/Version
B5: HOSTNAME | E5: 담당부서/담당자
B6: IP Address | E6: 비고
B10: 구분 | C10: 순번 | D10: 점검항목 | F10: 중요도 | G10: 점수 | H10: 점검기준 | I10: 보안점검 | O10: 이행점검
I11: 결과 | J11: 점수 | K11: 현황 | L11: 인터뷰 사항 | M11: 권고사항 | N11: 담당자 의견 | O11: 결과 | P11: 점수 | Q11: 현황 | R11: 담당자의견
B12: 1. 계정관리 | C12: U-01 | D12: root 계정 원격 접속 제한 | F12: 상 | G12: =IF(F12="상",10,IF(F12="중",8,6)) -> 10 | H12: [양호] 원격터미널 서비스를 사용하지 않거나, 사용 시 root 직접 접속을 차단한 경우 [취약] 원격터미널 서비스 사용 시 root 직접 접속을 허용한 경우 | J12: =IF(I12="N/A","N/A",(IF(I12="양호",1,IF(I12="위험수용",0.5,0))*$G12)) -> 0 | M12: =IF(OR(I12="취약",I12="수동점검"),대응방안!G4,"-") -> - | P12: =IF(O12="N/A","N/A",(IF(O12="양호",1,IF(O12="위험수용",0.5,0))*$G12)) -> 0
C13: U-02 | D13: 비밀번호 관리정책 설정 | F13: 상 | G13: =IF(F13="상",10,IF(F13="중",8,6)) -> 10 | H13: [양호] 비밀번호 관리 정책이 설정된 경우 [취약] 비밀번호 관리 정책이 설정되지 않은 경우 | J13: =IF(I13="N/A","N/A",(IF(I13="양호",1,IF(I13="위험수용",0.5,0))*$G13)) -> 0 | M13: =IF(OR(I13="취약",I13="수동점검"),대응방안!G5,"-") -> - | P13: =IF(O13="N/A","N/A",(IF(O13="양호",1,IF(O13="위험수용",0.5,0))*$G13)) -> 0
C14: U-03 | D14: 계정 잠금 임계값 설정 | F14: 상 | G14: =IF(F14="상",10,IF(F14="중",8,6)) -> 10 | H14: [양호] 계정 잠금 임계값이 10회 이하의 값으로 설정된 경우 [취약] 계정 잠금 임계값이 설정되어 있지 않거나, 10회 이하의 값으로 설정되지 않은 경우 | J14: =IF(I14="N/A","N/A",(IF(I14="양호",1,IF(I14="위험수용",0.5,0))*$G14)) -> 0 | M14: =IF(OR(I14="취약",I14="수동점검"),대응방안!G6,"-") -> - | P14: =IF(O14="N/A","N/A",(IF(O14="양호",1,IF(O14="위험수용",0.5,0))*$G14)) -> 0
C15: U-04 | D15: 비밀번호 파일 보호 | F15: 상 | G15: =IF(F15="상",10,IF(F15="중",8,6)) -> 10 | H15: [양호] 쉐도우 비밀번호를 사용하거나, 비밀번호를 암호화하여 저장하는 경우 [취약] 쉐도우 비밀번호를 사용하지 않고, 비밀번호를 암호화하여 저장하지 않는 경우 | J15: =IF(I15="N/A","N/A",(IF(I15="양호",1,IF(I15="위험수용",0.5,0))*$G15)) -> 0 | M15: =IF(OR(I15="취약",I15="수동점검"),대응방안!G7,"-") -> - | P15: =IF(O15="N/A","N/A",(IF(O15="양호",1,IF(O15="위험수용",0.5,0))*$G15)) -> 0
C16: U-05 | D16: root 이외의 UID가 '0' 금지 | F16: 중 | G16: =IF(F16="상",10,IF(F16="중",8,6)) -> 8 | H16: [양호] root 계정과 동일한 UID를 갖는 계정이 존재하지 않는 경우 [취약] root 계정과 동일한 UID를 갖는 계정이 존재하는 경우 | J16: =IF(I16="N/A","N/A",(IF(I16="양호",1,IF(I16="위험수용",0.5,0))*$G16)) -> 0 | M16: =IF(OR(I16="취약",I16="수동점검"),대응방안!G8,"-") -> - | P16: =IF(O16="N/A","N/A",(IF(O16="양호",1,IF(O16="위험수용",0.5,0))*$G16)) -> 0
C17: U-06 | D17: 사용자 계정 su 기능 제한 | F17: 상 | G17: =IF(F17="상",10,IF(F17="중",8,6)) -> 10 | H17: [양호] su 명령어를 특정 그룹에 속한 사용자만 사용하도록 제한된 경우 ※ 일반 사용자 계정 없이 root 계정만 사용하는 경우 su 명령어 사용 제한 불필요 [취약] su 명령어를 모든 사용자가 사용하도록 설정된 경우 | J17: =IF(I17="N/A","N/A",(IF(I17="양호",1,IF(I17="위험수용",0.5,0))*$G17)) -> 0 | M17: =IF(OR(I17="취약",I17="수동점검"),대응방안!G9,"-") -> - | P17: =IF(O17="N/A","N/A",(IF(O17="양호",1,IF(O17="위험수용",0.5,0))*$G17)) -> 0
C18: U-07 | D18: 불필요한 계정 제거 | F18: 하 | G18: =IF(F18="상",10,IF(F18="중",8,6)) -> 6 | H18: [양호] 불필요한 계정이 존재하지 않는 경우 [취약] 불필요한 계정이 존재하는 경우 | J18: =IF(I18="N/A","N/A",(IF(I18="양호",1,IF(I18="위험수용",0.5,0))*$G18)) -> 0 | M18: =IF(OR(I18="취약",I18="수동점검"),대응방안!G10,"-") -> - | P18: =IF(O18="N/A","N/A",(IF(O18="양호",1,IF(O18="위험수용",0.5,0))*$G18)) -> 0
C19: U-08 | D19: 관리자 그룹에 최소한의 계정 포함 | F19: 중 | G19: =IF(F19="상",10,IF(F19="중",8,6)) -> 8 | H19: [양호] 관리자 그룹에 불필요한 계정이 등록되어 있지 않은 경우 [취약] 관리자 그룹에 불필요한 계정이 등록된 경우 | J19: =IF(I19="N/A","N/A",(IF(I19="양호",1,IF(I19="위험수용",0.5,0))*$G19)) -> 0 | M19: =IF(OR(I19="취약",I19="수동점검"),대응방안!G11,"-") -> - | P19: =IF(O19="N/A","N/A",(IF(O19="양호",1,IF(O19="위험수용",0.5,0))*$G19)) -> 0
C20: U-09 | D20: 계정이 존재하지 않는 GID 금지 | F20: 하 | G20: =IF(F20="상",10,IF(F20="중",8,6)) -> 6 | H20: [양호] 시스템 관리나 운용에 불필요한 그룹이 제거된 경우 [취약] 시스템 관리나 운용에 불필요한 그룹이 존재하는 경우 | J20: =IF(I20="N/A","N/A",(IF(I20="양호",1,IF(I20="위험수용",0.5,0))*$G20)) -> 0 | M20: =IF(OR(I20="취약",I20="수동점검"),대응방안!G12,"-") -> - | P20: =IF(O20="N/A","N/A",(IF(O20="양호",1,IF(O20="위험수용",0.5,0))*$G20)) -> 0
C21: U-10 | D21: 동일한 UID 금지 | F21: 중 | G21: =IF(F21="상",10,IF(F21="중",8,6)) -> 8 | H21: [양호] 동일한 UID로 설정된 사용자 계정이 존재하지 않는 경우 [취약] 동일한 UID로 설정된 사용자 계정이 존재하는 경우 | J21: =IF(I21="N/A","N/A",(IF(I21="양호",1,IF(I21="위험수용",0.5,0))*$G21)) -> 0 | M21: =IF(OR(I21="취약",I21="수동점검"),대응방안!G13,"-") -> - | P21: =IF(O21="N/A","N/A",(IF(O21="양호",1,IF(O21="위험수용",0.5,0))*$G21)) -> 0
C22: U-11 | D22: 사용자 shell 점검 | F22: 하 | G22: =IF(F22="상",10,IF(F22="중",8,6)) -> 6 | H22: [양호] 로그인이 필요하지 않은 계정에 /bin/false(/sbin/nologin) 쉘이 부여된 경우 [취약] 로그인이 필요하지 않은 계정에 /bin/false(/sbin/nologin) 쉘이 부여되지 않은 경우 | J22: =IF(I22="N/A","N/A",(IF(I22="양호",1,IF(I22="위험수용",0.5,0))*$G22)) -> 0 | M22: =IF(OR(I22="취약",I22="수동점검"),대응방안!G14,"-") -> - | P22: =IF(O22="N/A","N/A",(IF(O22="양호",1,IF(O22="위험수용",0.5,0))*$G22)) -> 0
C23: U-12 | D23: 세션 종료 시간 설정 | F23: 하 | G23: =IF(F23="상",10,IF(F23="중",8,6)) -> 6 | H23: [양호] Session Timeout이 600초(10분) 이하로 설정된 경우 [취약] Session Timeout이 600초(10분) 이하로 설정되지 않은 경우 | J23: =IF(I23="N/A","N/A",(IF(I23="양호",1,IF(I23="위험수용",0.5,0))*$G23)) -> 0 | M23: =IF(OR(I23="취약",I23="수동점검"),대응방안!G15,"-") -> - | P23: =IF(O23="N/A","N/A",(IF(O23="양호",1,IF(O23="위험수용",0.5,0))*$G23)) -> 0
C24: U-13 | D24: 안전한 비밀번호 암호화 알고리즘 사용 | F24: 중 | G24: =IF(F24="상",10,IF(F24="중",8,6)) -> 8 | H24: [양호] SHA-2 이상의 안전한 비밀번호 암호화 알고리즘을 사용하는 경우 [취약] 취약한 비밀번호 암호화 알고리즘을 사용하는 경우 | J24: =IF(I24="N/A","N/A",(IF(I24="양호",1,IF(I24="위험수용",0.5,0))*$G24)) -> 0 | M24: =IF(OR(I24="취약",I24="수동점검"),대응방안!G16,"-") -> - | P24: =IF(O24="N/A","N/A",(IF(O24="양호",1,IF(O24="위험수용",0.5,0))*$G24)) -> 0
B25: 2. 파일 및 디렉터리 관리 | C25: U-14 | D25: root 홈, 패스 디렉터리 권한 및 패스 설정 | F25: 상 | G25: =IF(F25="상",10,IF(F25="중",8,6)) -> 10 | H25: [양호] PATH 환경변수에 “.” 이 맨 앞이나 중간에 포함되지 않은 경우 [취약] PATH 환경변수에 “.” 이 맨 앞이나 중간에 포함된 경우 | J25: =IF(I25="N/A","N/A",(IF(I25="양호",1,IF(I25="위험수용",0.5,0))*$G25)) -> 0 | M25: =IF(OR(I25="취약",I25="수동점검"),대응방안!G17,"-") -> - | P25: =IF(O25="N/A","N/A",(IF(O25="양호",1,IF(O25="위험수용",0.5,0))*$G25)) -> 0
C26: U-15 | D26: 파일 및 디렉터리 소유자 설정 | F26: 상 | G26: =IF(F26="상",10,IF(F26="중",8,6)) -> 10 | H26: [양호] 소유자가 존재하지 않는 파일 및 디렉터리가 존재하지 않는 경우 [취약] 소유자가 존재하지 않는 파일 및 디렉터리가 존재하는 경우 | J26: =IF(I26="N/A","N/A",(IF(I26="양호",1,IF(I26="위험수용",0.5,0))*$G26)) -> 0 | M26: =IF(OR(I26="취약",I26="수동점검"),대응방안!G18,"-") -> - | P26: =IF(O26="N/A","N/A",(IF(O26="양호",1,IF(O26="위험수용",0.5,0))*$G26)) -> 0
C27: U-16 | D27: /etc/passwd 파일 소유자 및 권한 설정 | F27: 상 | G27: =IF(F27="상",10,IF(F27="중",8,6)) -> 10 | H27: [양호] /etc/passwd 파일의 소유자가 root이고, 권한이 644 이하인 경우 [취약] /etc/passwd 파일의 소유자가 root가 아니거나, 권한이 644 이하가 아닌 경우 | J27: =IF(I27="N/A","N/A",(IF(I27="양호",1,IF(I27="위험수용",0.5,0))*$G27)) -> 0 | M27: =IF(OR(I27="취약",I27="수동점검"),대응방안!G19,"-") -> - | P27: =IF(O27="N/A","N/A",(IF(O27="양호",1,IF(O27="위험수용",0.5,0))*$G27)) -> 0
C28: U-17 | D28: 시스템 시작 스크립트 권한 설정 | F28: 상 | G28: =IF(F28="상",10,IF(F28="중",8,6)) -> 10 | H28: [양호] 시스템 시작 스크립트 파일의 소유자가 root이고, 일반 사용자의 쓰기 권한이 제거된 경우 [취약] 시스템 시작 스크립트 파일의 소유자가 root가 아니거나, 일반 사용자의 쓰기 권한이 부여된 경우 | J28: =IF(I28="N/A","N/A",(IF(I28="양호",1,IF(I28="위험수용",0.5,0))*$G28)) -> 0 | M28: =IF(OR(I28="취약",I28="수동점검"),대응방안!G20,"-") -> - | P28: =IF(O28="N/A","N/A",(IF(O28="양호",1,IF(O28="위험수용",0.5,0))*$G28)) -> 0
C29: U-18 | D29: /etc/shadow 파일의 소유자가 root이고, 권한이 400 이하인 경우 | F29: 상 | G29: =IF(F29="상",10,IF(F29="중",8,6)) -> 10 | H29: [양호] /etc/shadow 파일의 소유자가 root이고, 권한이 400 이하인 경우 [취약] /etc/shadow 파일의 소유자가 root가 아니거나, 권한이 400 이하가 아닌 경우 | J29: =IF(I29="N/A","N/A",(IF(I29="양호",1,IF(I29="위험수용",0.5,0))*$G29)) -> 0 | M29: =IF(OR(I29="취약",I29="수동점검"),대응방안!G21,"-") -> - | P29: =IF(O29="N/A","N/A",(IF(O29="양호",1,IF(O29="위험수용",0.5,0))*$G29)) -> 0
C30: U-19 | D30: /etc/hosts 파일 소유자 및 권한 설정 | F30: 상 | G30: =IF(F30="상",10,IF(F30="중",8,6)) -> 10 | H30: [양호] /etc/hosts 파일의 소유자가 root이고, 권한이 644 이하인 경우 [취약] /etc/hosts 파일의 소유자가 root가 아니거나, 권한이 644 이하가 아닌 경우 | J30: =IF(I30="N/A","N/A",(IF(I30="양호",1,IF(I30="위험수용",0.5,0))*$G30)) -> 0 | M30: =IF(OR(I30="취약",I30="수동점검"),대응방안!G22,"-") -> - | P30: =IF(O30="N/A","N/A",(IF(O30="양호",1,IF(O30="위험수용",0.5,0))*$G30)) -> 0
C31: U-20 | D31: /etc/(x)inetd.conf 파일 소유자 및 권한 설정 | F31: 상 | G31: =IF(F31="상",10,IF(F31="중",8,6)) -> 10 | H31: [양호] /etc/(x)inetd.conf 파일의 소유자가 root이고, 권한이 600 이하인 경우 [취약] /etc/(x)inetd.conf 파일의 소유자가 root가 아니거나, 권한이 600 이하가 아닌 경우 | J31: =IF(I31="N/A","N/A",(IF(I31="양호",1,IF(I31="위험수용",0.5,0))*$G31)) -> 0 | M31: =IF(OR(I31="취약",I31="수동점검"),대응방안!G23,"-") -> - | P31: =IF(O31="N/A","N/A",(IF(O31="양호",1,IF(O31="위험수용",0.5,0))*$G31)) -> 0
C32: U-21 | D32: /etc/(r)syslog.conf 파일 소유자 및 권한 설정 | F32: 상 | G32: =IF(F32="상",10,IF(F32="중",8,6)) -> 10 | H32: [양호] /etc/(r)syslog.conf 파일의 소유자가 root(또는 bin, sys)이고, 권한이 640 이하인 경우 [취약] /etc/(r)syslog.conf 파일의 소유자가 root(또는 bin, sys)가 아니거나, 권한이 640 이하가 아닌 경우 | J32: =IF(I32="N/A","N/A",(IF(I32="양호",1,IF(I32="위험수용",0.5,0))*$G32)) -> 0 | M32: =IF(OR(I32="취약",I32="수동점검"),대응방안!G24,"-") -> - | P32: =IF(O32="N/A","N/A",(IF(O32="양호",1,IF(O32="위험수용",0.5,0))*$G32)) -> 0
C33: U-22 | D33: /etc/services 파일 소유자 및 권한 설정 | F33: 상 | G33: =IF(F33="상",10,IF(F33="중",8,6)) -> 10 | H33: [양호] /etc/services 파일의 소유자가 root(또는 bin, sys)이고, 권한이 644 이하인 경우 [취약] /etc/services 파일의 소유자가 root(또는 bin, sys)가 아니거나, 권한이 644 이하가 아닌 경우 | J33: =IF(I33="N/A","N/A",(IF(I33="양호",1,IF(I33="위험수용",0.5,0))*$G33)) -> 0 | M33: =IF(OR(I33="취약",I33="수동점검"),대응방안!G25,"-") -> - | P33: =IF(O33="N/A","N/A",(IF(O33="양호",1,IF(O33="위험수용",0.5,0))*$G33)) -> 0
C34: U-23 | D34: SUID, SGID, Sticky bit 설정 파일 점검 | F34: 상 | G34: =IF(F34="상",10,IF(F34="중",8,6)) -> 10 | H34: [양호] 주요 실행 파일의 권한에 SUID와 SGID에 대한 설정이 부여되어 있지 않은 경우 [취약] 주요 실행 파일의 권한에 SUID와 SGID에 대한 설정이 부여된 경우 | J34: =IF(I34="N/A","N/A",(IF(I34="양호",1,IF(I34="위험수용",0.5,0))*$G34)) -> 0 | M34: =IF(OR(I34="취약",I34="수동점검"),대응방안!G26,"-") -> - | P34: =IF(O34="N/A","N/A",(IF(O34="양호",1,IF(O34="위험수용",0.5,0))*$G34)) -> 0
C35: U-24 | D35: 사용자, 시스템 환경변수 파일 소유자 및 권한 설정 | F35: 상 | G35: =IF(F35="상",10,IF(F35="중",8,6)) -> 10 | H35: [양호] 홈 디렉터리 환경변수 파일 소유자가 root 또는 해당 계정으로 지정되어 있고, 홈 디렉터리 환경변수 파일에 root 계정과 소유자만 쓰기 권한이 부여된 경우 [취약] 홈 디렉터리 환경변수 파일 소유자가 root 또는 해당 계정으로 지정되지 않거나, 홈 디렉터리 환경변수 파일에 root 계정과 소유자 외에 쓰기 권한이 부여된 경우 | J35: =IF(I35="N/A","N/A",(IF(I35="양호",1,IF(I35="위험수용",0.5,0))*$G35)) -> 0 | M35: =IF(OR(I35="취약",I35="수동점검"),대응방안!G27,"-") -> - | P35: =IF(O35="N/A","N/A",(IF(O35="양호",1,IF(O35="위험수용",0.5,0))*$G35)) -> 0
C36: U-25 | D36: world writable 파일 점검 | F36: 상 | G36: =IF(F36="상",10,IF(F36="중",8,6)) -> 10 | H36: [양호] world writable 파일이 존재하지 않거나, 존재 시 설정 이유를 인지하고 있는 경우 [취약] world writable 파일이 존재하나 설정 이유를 인지하지 못하고 있는 경우 | J36: =IF(I36="N/A","N/A",(IF(I36="양호",1,IF(I36="위험수용",0.5,0))*$G36)) -> 0 | M36: =IF(OR(I36="취약",I36="수동점검"),대응방안!G28,"-") -> - | P36: =IF(O36="N/A","N/A",(IF(O36="양호",1,IF(O36="위험수용",0.5,0))*$G36)) -> 0
C37: U-26 | D37: /dev에 존재하지 않는 device 파일 점검 | F37: 상 | G37: =IF(F37="상",10,IF(F37="중",8,6)) -> 10 | H37: [양호] /dev 디렉터리에 대한 파일 점검 후 존재하지 않는 device 파일을 제거한 경우 [취약] /dev 디렉터리에 대한 파일 미점검 또는 존재하지 않는 device 파일을 방치한 경우 | J37: =IF(I37="N/A","N/A",(IF(I37="양호",1,IF(I37="위험수용",0.5,0))*$G37)) -> 0 | M37: =IF(OR(I37="취약",I37="수동점검"),대응방안!G29,"-") -> - | P37: =IF(O37="N/A","N/A",(IF(O37="양호",1,IF(O37="위험수용",0.5,0))*$G37)) -> 0
... C44: U-33 | D44: 숨겨진 파일 및 디렉토리 검색 및 제거 | F44: 하 | G44: =IF(F44="상",10,IF(F44="중",8,6)) -> 6 | H44: [양호] 불필요하거나 의심스러운 숨겨진 파일 및 디렉토리를 제거한 경우 [취약] 불필요하거나 의심스러운 숨겨진 파일 및 디렉토리를 제거하지 않은 경우 | J44: =IF(I44="N/A","N/A",(IF(I44="양호",1,IF(I44="위험수용",0.5,0))*$G44)) -> 0 | M44: =IF(OR(I44="취약",I44="수동점검"),대응방안!G36,"-") -> - | P44: =IF(O44="N/A","N/A",(IF(O44="양호",1,IF(O44="위험수용",0.5,0))*$G44)) -> 0
B45: 3. 서비스 관리 | C45: U-34 | D45: Finger 서비스 비활성화 | F45: 상 | G45: =IF(F45="상",10,IF(F45="중",8,6)) -> 10 | H45: [양호] Finger 서비스가 비활성화된 경우 [취약] Finger 서비스가 활성화된 경우 | J45: =IF(I45="N/A","N/A",(IF(I45="양호",1,IF(I45="위험수용",0.5,0))*$G45)) -> 0 | M45: =IF(OR(I45="취약",I45="수동점검"),대응방안!G37,"-") -> - | P45: =IF(O45="N/A","N/A",(IF(O45="양호",1,IF(O45="위험수용",0.5,0))*$G45)) -> 0
C46: U-35 | D46: 공유 서비스에 대한 익명 접근 제한 설정 | F46: 상 | G46: =IF(F46="상",10,IF(F46="중",8,6)) -> 10 | H46: [양호] 공유 서비스에 대해 익명 접근을 제한한 경우 [취약] 공유 서비스에 대해 익명 접근을 허용한 경우 | J46: =IF(I46="N/A","N/A",(IF(I46="양호",1,IF(I46="위험수용",0.5,0))*$G46)) -> 0 | M46: =IF(OR(I46="취약",I46="수동점검"),대응방안!G38,"-") -> - | P46: =IF(O46="N/A","N/A",(IF(O46="양호",1,IF(O46="위험수용",0.5,0))*$G46)) -> 0
C47: U-36 | D47: r 계열 서비스 비활성화 | F47: 상 | G47: =IF(F47="상",10,IF(F47="중",8,6)) -> 10 | H47: [양호] 불필요한 r 계열 서비스가 비활성화된 경우 [취약] 불필요한 r 계열 서비스가 활성화된 경우 | J47: =IF(I47="N/A","N/A",(IF(I47="양호",1,IF(I47="위험수용",0.5,0))*$G47)) -> 0 | M47: =IF(OR(I47="취약",I47="수동점검"),대응방안!G39,"-") -> - | P47: =IF(O47="N/A","N/A",(IF(O47="양호",1,IF(O47="위험수용",0.5,0))*$G47)) -> 0
C48: U-37 | D48: crontab 설정파일 권한 설정 미흡 | F48: 상 | G48: =IF(F48="상",10,IF(F48="중",8,6)) -> 10 | H48: [양호] crontab 및 at 명령어에 일반 사용자 실행 권한이 제거되어 있으며, cron 및 at 관련 파일 권한이 640 이하인 경우 [취약] crontab 및 at 명령어에 일반 사용자 실행 권한이 부여되어 있으며, cron 및 at 관련 파일 권한이 640 이상인 경우 | J48: =IF(I48="N/A","N/A",(IF(I48="양호",1,IF(I48="위험수용",0.5,0))*$G48)) -> 0 | M48: =IF(OR(I48="취약",I48="수동점검"),대응방안!G40,"-") -> - | P48: =IF(O48="N/A","N/A",(IF(O48="양호",1,IF(O48="위험수용",0.5,0))*$G48)) -> 0
C49: U-38 | D49: DoS 공격에 취약한 서비스 비활성화 | F49: 상 | G49: =IF(F49="상",10,IF(F49="중",8,6)) -> 10 | H49: [양호] DoS 공격에 취약한 서비스가 비활성화된 경우 [취약] DoS 공격에 취약한 서비스가 활성화된 경우 | J49: =IF(I49="N/A","N/A",(IF(I49="양호",1,IF(I49="위험수용",0.5,0))*$G49)) -> 0 | M49: =IF(OR(I49="취약",I49="수동점검"),대응방안!G41,"-") -> - | P49: =IF(O49="N/A","N/A",(IF(O49="양호",1,IF(O49="위험수용",0.5,0))*$G49)) -> 0
C50: U-39 | D50: 불필요한 NFS 서비스 비활성화 | F50: 상 | G50: =IF(F50="상",10,IF(F50="중",8,6)) -> 10 | H50: [양호] 불필요한 NFS 서비스 관련 데몬이 비활성화된 경우 [취약] 불필요한 NFS 서비스 관련 데몬이 활성화된 경우 | J50: =IF(I50="N/A","N/A",(IF(I50="양호",1,IF(I50="위험수용",0.5,0))*$G50)) -> 0 | M50: =IF(OR(I50="취약",I50="수동점검"),대응방안!G42,"-") -> - | P50: =IF(O50="N/A","N/A",(IF(O50="양호",1,IF(O50="위험수용",0.5,0))*$G50)) -> 0
C51: U-40 | D51: NFS 접근 통제 | F51: 상 | G51: =IF(F51="상",10,IF(F51="중",8,6)) -> 10 | H51: [양호] 접근 통제가 설정되어 있으며 NFS 설정 파일 접근 권한이 644 이하인 경우 [취약] 접근 통제가 설정되어 있지 않고 NFS 설정 파일 접근 권한이 644를 초과하는 경우 | J51: =IF(I51="N/A","N/A",(IF(I51="양호",1,IF(I51="위험수용",0.5,0))*$G51)) -> 0 | M51: =IF(OR(I51="취약",I51="수동점검"),대응방안!G43,"-") -> - | P51: =IF(O51="N/A","N/A",(IF(O51="양호",1,IF(O51="위험수용",0.5,0))*$G51)) -> 0
...
